<?xml version="1.0" encoding="utf-8"?><testsuites><testsuite name="pytest" errors="1" failures="0" skipped="0" tests="1" time="1.001" timestamp="2024-09-24T12:01:12.305117+00:00" hostname="ip-172-31-30-46"><testcase classname="" name="tests.unit.test_app" time="0.000"><error message="collection failure">tests/unit/test_app.py:3: in &lt;module&gt;
    subprocess.run(["/tests/unit/test_app.sh"])
/usr/lib/python3.9/subprocess.py:505: in run
    with Popen(*popenargs, **kwargs) as process:
/usr/lib/python3.9/subprocess.py:951: in __init__
    self._execute_child(args, executable, preexec_fn, close_fds,
/usr/lib/python3.9/subprocess.py:1837: in _execute_child
    raise child_exception_type(errno_num, err_msg, err_filename)
E   FileNotFoundError: [Errno 2] No such file or directory: '/tests/unit/test_app.sh'</error></testcase></testsuite></testsuites>